{
 "cells": [
  {
   "cell_type": "code",
   "execution_count": 1,
   "id": "8f278b98",
   "metadata": {},
   "outputs": [],
   "source": [
    "assert sum([1, 2, 3]) == 6, \"Should be 6\""
   ]
  },
  {
   "cell_type": "code",
   "execution_count": 2,
   "id": "70880ed0",
   "metadata": {},
   "outputs": [
    {
     "ename": "AssertionError",
     "evalue": "Should be 6",
     "output_type": "error",
     "traceback": [
      "\u001b[1;31m---------------------------------------------------------------------------\u001b[0m",
      "\u001b[1;31mAssertionError\u001b[0m                            Traceback (most recent call last)",
      "Input \u001b[1;32mIn [2]\u001b[0m, in \u001b[0;36m<cell line: 1>\u001b[1;34m()\u001b[0m\n\u001b[1;32m----> 1\u001b[0m \u001b[38;5;28;01massert\u001b[39;00m \u001b[38;5;28msum\u001b[39m([\u001b[38;5;241m1\u001b[39m, \u001b[38;5;241m1\u001b[39m, \u001b[38;5;241m1\u001b[39m]) \u001b[38;5;241m==\u001b[39m \u001b[38;5;241m6\u001b[39m, \u001b[38;5;124m\"\u001b[39m\u001b[38;5;124mShould be 6\u001b[39m\u001b[38;5;124m\"\u001b[39m\n",
      "\u001b[1;31mAssertionError\u001b[0m: Should be 6"
     ]
    }
   ],
   "source": [
    "assert sum([1, 1, 1]) == 6, \"Should be 6\""
   ]
  },
  {
   "cell_type": "code",
   "execution_count": 3,
   "id": "377b014a",
   "metadata": {},
   "outputs": [
    {
     "name": "stdout",
     "output_type": "stream",
     "text": [
      "Everything passed\n"
     ]
    }
   ],
   "source": [
    "def test_sum():\n",
    "    assert sum([1, 2, 3]) == 6, \"Should be 6\"\n",
    "\n",
    "if __name__ == \"__main__\":\n",
    "    test_sum()\n",
    "    print(\"Everything passed\")"
   ]
  },
  {
   "cell_type": "code",
   "execution_count": 6,
   "id": "1e44d3d6",
   "metadata": {},
   "outputs": [
    {
     "ename": "AssertionError",
     "evalue": "Should be 6",
     "output_type": "error",
     "traceback": [
      "\u001b[1;31m---------------------------------------------------------------------------\u001b[0m",
      "\u001b[1;31mAssertionError\u001b[0m                            Traceback (most recent call last)",
      "Input \u001b[1;32mIn [6]\u001b[0m, in \u001b[0;36m<cell line: 7>\u001b[1;34m()\u001b[0m\n\u001b[0;32m      7\u001b[0m \u001b[38;5;28;01mif\u001b[39;00m \u001b[38;5;18m__name__\u001b[39m \u001b[38;5;241m==\u001b[39m \u001b[38;5;124m\"\u001b[39m\u001b[38;5;124m__main__\u001b[39m\u001b[38;5;124m\"\u001b[39m:\n\u001b[0;32m      8\u001b[0m     test_sum()\n\u001b[1;32m----> 9\u001b[0m     \u001b[43mtest_sum_tuple\u001b[49m\u001b[43m(\u001b[49m\u001b[43m)\u001b[49m\n\u001b[0;32m     10\u001b[0m     \u001b[38;5;28mprint\u001b[39m(\u001b[38;5;124m\"\u001b[39m\u001b[38;5;124mEverything passed\u001b[39m\u001b[38;5;124m\"\u001b[39m)\n",
      "Input \u001b[1;32mIn [6]\u001b[0m, in \u001b[0;36mtest_sum_tuple\u001b[1;34m()\u001b[0m\n\u001b[0;32m      4\u001b[0m \u001b[38;5;28;01mdef\u001b[39;00m \u001b[38;5;21mtest_sum_tuple\u001b[39m():\n\u001b[1;32m----> 5\u001b[0m     \u001b[38;5;28;01massert\u001b[39;00m \u001b[38;5;28msum\u001b[39m((\u001b[38;5;241m1\u001b[39m, \u001b[38;5;241m2\u001b[39m, \u001b[38;5;241m2\u001b[39m)) \u001b[38;5;241m==\u001b[39m \u001b[38;5;241m6\u001b[39m, \u001b[38;5;124m\"\u001b[39m\u001b[38;5;124mShould be 6\u001b[39m\u001b[38;5;124m\"\u001b[39m\n",
      "\u001b[1;31mAssertionError\u001b[0m: Should be 6"
     ]
    }
   ],
   "source": [
    "def test_sum():\n",
    "    assert sum([1, 2, 3]) == 6, \"Should be 6\"\n",
    "\n",
    "def test_sum_tuple():\n",
    "    assert sum((1, 2, 2)) == 6, \"Should be 6\"\n",
    "\n",
    "if __name__ == \"__main__\":\n",
    "    test_sum()\n",
    "    test_sum_tuple()\n",
    "    print(\"Everything passed\")"
   ]
  },
  {
   "cell_type": "code",
   "execution_count": 7,
   "id": "d9586cbb",
   "metadata": {},
   "outputs": [
    {
     "name": "stderr",
     "output_type": "stream",
     "text": [
      "E\n",
      "======================================================================\n",
      "ERROR: C:\\Users\\klemm\\AppData\\Roaming\\jupyter\\runtime\\kernel-4c6aa8bb-0a16-4db9-b499-ea9e0e7dd4b4 (unittest.loader._FailedTest)\n",
      "----------------------------------------------------------------------\n",
      "AttributeError: module '__main__' has no attribute 'C:\\Users\\klemm\\AppData\\Roaming\\jupyter\\runtime\\kernel-4c6aa8bb-0a16-4db9-b499-ea9e0e7dd4b4'\n",
      "\n",
      "----------------------------------------------------------------------\n",
      "Ran 1 test in 0.001s\n",
      "\n",
      "FAILED (errors=1)\n"
     ]
    },
    {
     "ename": "SystemExit",
     "evalue": "True",
     "output_type": "error",
     "traceback": [
      "An exception has occurred, use %tb to see the full traceback.\n",
      "\u001b[1;31mSystemExit\u001b[0m\u001b[1;31m:\u001b[0m True\n"
     ]
    },
    {
     "name": "stderr",
     "output_type": "stream",
     "text": [
      "C:\\Users\\klemm\\anaconda3\\lib\\site-packages\\IPython\\core\\interactiveshell.py:3377: UserWarning: To exit: use 'exit', 'quit', or Ctrl-D.\n",
      "  warn(\"To exit: use 'exit', 'quit', or Ctrl-D.\", stacklevel=1)\n"
     ]
    }
   ],
   "source": [
    "import unittest\n",
    "\n",
    "\n",
    "class TestSum(unittest.TestCase):\n",
    "\n",
    "    def test_sum(self):\n",
    "        self.assertEqual(sum([1, 2, 3]), 6, \"Should be 6\")\n",
    "\n",
    "    def test_sum_tuple(self):\n",
    "        self.assertEqual(sum((1, 2, 2)), 6, \"Should be 6\")\n",
    "\n",
    "if __name__ == '__main__':\n",
    "    unittest.main()"
   ]
  },
  {
   "cell_type": "code",
   "execution_count": 8,
   "id": "61899966",
   "metadata": {},
   "outputs": [],
   "source": [
    "import unittest"
   ]
  },
  {
   "cell_type": "code",
   "execution_count": 10,
   "id": "252160c1",
   "metadata": {},
   "outputs": [],
   "source": [
    "def test_sum():\n",
    "    assert sum([1, 2, 3]) == 6, \"Should be 6\"\n",
    "\n",
    "def test_sum_tuple():\n",
    "    assert sum((1, 2, 2)) == 6, \"Should be 6\""
   ]
  },
  {
   "cell_type": "markdown",
   "id": "5370dd4b",
   "metadata": {},
   "source": [
    "PS C:\\Users\\klemm\\OneDrive\\Desktop> pip install nose2\n",
    "Collecting nose2\n",
    "  Downloading nose2-0.11.0-py2.py3-none-any.whl (144 kB)\n",
    "     ---------------------------------------- 144.1/144.1 KB 2.8 MB/s eta 0:00:00\n",
    "Collecting coverage>=4.4.1\n",
    "  Downloading coverage-6.4.1-cp310-cp310-win_amd64.whl (187 kB)\n",
    "     ---------------------------------------- 187.4/187.4 KB 5.5 MB/s eta 0:00:00\n",
    "Requirement already satisfied: six>=1.7 in c:\\users\\klemm\\appdata\\local\\packages\\pythonsoftwarefoundation.python.3.10_qbz5n2kfra8p0\\localcache\\local-packages\\python310\\site-packages (from nose2) (1.16.0)\n",
    "Installing collected packages: coverage, nose2\n",
    "  WARNING: The scripts coverage-3.10.exe, coverage.exe and coverage3.exe are installed in 'C:\\Users\\klemm\\AppData\\Local\\Packages\\PythonSoftwareFoundation.Python.3.10_qbz5n2kfra8p0\\LocalCache\\local-packages\\Python310\\Scripts' which is not on PATH.\n",
    "  Consider adding this directory to PATH or, if you prefer to suppress this warning, use --no-warn-script-location.\n",
    "  WARNING: The scripts nose2-3.8.exe and nose2.exe are installed in 'C:\\Users\\klemm\\AppData\\Local\\Packages\\PythonSoftwareFoundation.Python.3.10_qbz5n2kfra8p0\\LocalCache\\local-packages\\Python310\\Scripts' which is not on PATH.\n",
    "  Consider adding this directory to PATH or, if you prefer to suppress this warning, use --no-warn-script-location.\n",
    "Successfully installed coverage-6.4.1 nose2-0.11.0\n",
    "WARNING: You are using pip version 22.0.4; however, version 22.1.2 is available.\n",
    "You should consider upgrading via the 'C:\\Users\\klemm\\AppData\\Local\\Microsoft\\WindowsApps\\PythonSoftwareFoundation.Python.3.10_qbz5n2kfra8p0\\python.exe -m pip install --upgrade pip' command.\n",
    "PS C:\\Users\\klemm\\OneDrive\\Desktop> python -m nose2\n",
    ".F.\n",
    "======================================================================\n",
    "FAIL: test_sum_tuple (test.TestSum)\n",
    "----------------------------------------------------------------------\n",
    "Traceback (most recent call last):\n",
    "  File \"C:\\Users\\klemm\\OneDrive\\Desktop\\testing\\test.py\", line 10, in test_sum_tuple\n",
    "    self.assertEqual(sum((1, 2, 2)), 6, \"Should be 6\")\n",
    "AssertionError: 5 != 6 : Should be 6\n",
    "\n",
    "----------------------------------------------------------------------\n",
    "Ran 3 tests in 0.000s\n",
    "\n",
    "FAILED (failures=1)\n",
    "PS C:\\Users\\klemm\\OneDrive\\Desktop> cd sdev220\n",
    "PS C:\\Users\\klemm\\OneDrive\\Desktop\\sdev220> cd M05ProgramAssign\n",
    "PS C:\\Users\\klemm\\OneDrive\\Desktop\\sdev220\\M05ProgramAssign> python -m unittest test\n",
    ".\n",
    "----------------------------------------------------------------------\n",
    "Ran 1 test in 0.000s\n",
    "\n",
    "OK\n",
    "PS C:\\Users\\klemm\\OneDrive\\Desktop\\sdev220\\M05ProgramAssign> python -m unittest discover\n",
    ".\n",
    "----------------------------------------------------------------------\n",
    "Ran 1 test in 0.000s\n",
    "\n",
    "OK\n",
    "PS C:\\Users\\klemm\\OneDrive\\Desktop\\sdev220\\M05ProgramAssign> python -m unittest discover -s tests\n",
    "Traceback (most recent call last):\n",
    "  File \"C:\\Program Files\\WindowsApps\\PythonSoftwareFoundation.Python.3.10_3.10.1520.0_x64__qbz5n2kfra8p0\\lib\\runpy.py\", line 196, in _run_module_as_main\n",
    "    return _run_code(code, main_globals, None,\n",
    "  File \"C:\\Program Files\\WindowsApps\\PythonSoftwareFoundation.Python.3.10_3.10.1520.0_x64__qbz5n2kfra8p0\\lib\\runpy.py\", line 86, in _run_code\n",
    "    exec(code, run_globals)\n",
    "  File \"C:\\Program Files\\WindowsApps\\PythonSoftwareFoundation.Python.3.10_3.10.1520.0_x64__qbz5n2kfra8p0\\lib\\unittest\\__main__.py\", line 18, in <module>\n",
    "    main(module=None)\n",
    "  File \"C:\\Program Files\\WindowsApps\\PythonSoftwareFoundation.Python.3.10_3.10.1520.0_x64__qbz5n2kfra8p0\\lib\\unittest\\main.py\", line 100, in __init__\n",
    "    self.parseArgs(argv)\n",
    "  File \"C:\\Program Files\\WindowsApps\\PythonSoftwareFoundation.Python.3.10_3.10.1520.0_x64__qbz5n2kfra8p0\\lib\\unittest\\main.py\", line 124, in parseArgs\n",
    "    self._do_discovery(argv[2:])\n",
    "  File \"C:\\Program Files\\WindowsApps\\PythonSoftwareFoundation.Python.3.10_3.10.1520.0_x64__qbz5n2kfra8p0\\lib\\unittest\\main.py\", line 244, in _do_discovery\n",
    "    self.createTests(from_discovery=True, Loader=Loader)\n",
    "  File \"C:\\Program Files\\WindowsApps\\PythonSoftwareFoundation.Python.3.10_3.10.1520.0_x64__qbz5n2kfra8p0\\lib\\unittest\\main.py\", line 154, in createTests\n",
    "    self.test = loader.discover(self.start, self.pattern, self.top)\n",
    "  File \"C:\\Program Files\\WindowsApps\\PythonSoftwareFoundation.Python.3.10_3.10.1520.0_x64__qbz5n2kfra8p0\\lib\\unittest\\loader.py\", line 346, in discover\n",
    "    raise ImportError('Start directory is not importable: %r' % start_dir)\n",
    "ImportError: Start directory is not importable: 'tests'\n",
    "PS C:\\Users\\klemm\\OneDrive\\Desktop\\sdev220\\M05ProgramAssign> python -m unittest discover -s tests -t src\n",
    "Traceback (most recent call last):\n",
    "  File \"C:\\Program Files\\WindowsApps\\PythonSoftwareFoundation.Python.3.10_3.10.1520.0_x64__qbz5n2kfra8p0\\lib\\runpy.py\", line 196, in _run_module_as_main\n",
    "    return _run_code(code, main_globals, None,\n",
    "  File \"C:\\Program Files\\WindowsApps\\PythonSoftwareFoundation.Python.3.10_3.10.1520.0_x64__qbz5n2kfra8p0\\lib\\runpy.py\", line 86, in _run_code\n",
    "    exec(code, run_globals)\n",
    "  File \"C:\\Program Files\\WindowsApps\\PythonSoftwareFoundation.Python.3.10_3.10.1520.0_x64__qbz5n2kfra8p0\\lib\\unittest\\__main__.py\", line 18, in <module>\n",
    "    main(module=None)\n",
    "  File \"C:\\Program Files\\WindowsApps\\PythonSoftwareFoundation.Python.3.10_3.10.1520.0_x64__qbz5n2kfra8p0\\lib\\unittest\\main.py\", line 100, in __init__\n",
    "    self.parseArgs(argv)\n",
    "  File \"C:\\Program Files\\WindowsApps\\PythonSoftwareFoundation.Python.3.10_3.10.1520.0_x64__qbz5n2kfra8p0\\lib\\unittest\\main.py\", line 124, in parseArgs\n",
    "    self._do_discovery(argv[2:])\n",
    "  File \"C:\\Program Files\\WindowsApps\\PythonSoftwareFoundation.Python.3.10_3.10.1520.0_x64__qbz5n2kfra8p0\\lib\\unittest\\main.py\", line 244, in _do_discovery\n",
    "    self.createTests(from_discovery=True, Loader=Loader)\n",
    "  File \"C:\\Program Files\\WindowsApps\\PythonSoftwareFoundation.Python.3.10_3.10.1520.0_x64__qbz5n2kfra8p0\\lib\\unittest\\main.py\", line 154, in createTests\n",
    "    self.test = loader.discover(self.start, self.pattern, self.top)\n",
    "  File \"C:\\Program Files\\WindowsApps\\PythonSoftwareFoundation.Python.3.10_3.10.1520.0_x64__qbz5n2kfra8p0\\lib\\unittest\\loader.py\", line 346, in discover\n",
    "    raise ImportError('Start directory is not importable: %r' % start_dir)\n",
    "ImportError: Start directory is not importable: 'tests'\n",
    "PS C:\\Users\\klemm\\OneDrive\\Desktop\\sdev220\\M05ProgramAssign>"
   ]
  },
  {
   "cell_type": "code",
   "execution_count": null,
   "id": "eb0dbec8",
   "metadata": {},
   "outputs": [],
   "source": []
  }
 ],
 "metadata": {
  "kernelspec": {
   "display_name": "Python 3 (ipykernel)",
   "language": "python",
   "name": "python3"
  },
  "language_info": {
   "codemirror_mode": {
    "name": "ipython",
    "version": 3
   },
   "file_extension": ".py",
   "mimetype": "text/x-python",
   "name": "python",
   "nbconvert_exporter": "python",
   "pygments_lexer": "ipython3",
   "version": "3.9.12"
  }
 },
 "nbformat": 4,
 "nbformat_minor": 5
}
